{
 "cells": [
  {
   "cell_type": "code",
   "execution_count": 2,
   "metadata": {},
   "outputs": [],
   "source": [
    "import pandas as pd\n",
    "import pickle\n",
    "import seaborn as sns\n",
    "import matplotlib.pyplot as plt\n",
    "import numpy as np\n",
    "from sklearn.model_selection import KFold , cross_val_score\n",
    "from sklearn import metrics \n",
    "from matplotlib import pyplot as plt\n",
    "from numpy import mean, absolute\n",
    "import openpyxl\n",
    "from sklearn.linear_model import LogisticRegression\n",
    "from matplotlib import pyplot\n",
    "from tensorflow.keras.models import load_model\n",
    "from sklearn.metrics import log_loss, confusion_matrix, roc_auc_score, recall_score, precision_score, average_precision_score, f1_score, classification_report, accuracy_score, plot_roc_curve, plot_precision_recall_curve, plot_confusion_matrix"
   ]
  },
  {
   "cell_type": "code",
   "execution_count": 3,
   "metadata": {},
   "outputs": [],
   "source": [
    "# Import feature list\n",
    "infile = open('../01_solution_probability_model/01_data/FINALsmallSampleSet_3months_without_duplicates.pkl','rb')\n",
    "import_file = pickle.load(infile)\n",
    "infile.close()\n",
    "df = import_file\n",
    "feature_cols = list(df.columns)"
   ]
  },
  {
   "cell_type": "code",
   "execution_count": 8,
   "metadata": {},
   "outputs": [],
   "source": [
    "\"\"\"\n",
    "function to predict y and to calculate all scores neccessary for fairness evaluation\n",
    "\"\"\"\n",
    "def get_metrics(clf,X,y,cv):\n",
    "\n",
    "    scores_a = cross_val_score(clf, X, y, scoring='accuracy', cv=cv, n_jobs=-1)\n",
    "    a = mean(absolute(scores_a))\n",
    "    scores_p = cross_val_score(clf, X, y, scoring='precision', cv=cv, n_jobs=-1)\n",
    "    p = mean(absolute(scores_p))\n",
    "    scores_r = cross_val_score(clf, X, y, scoring='recall', cv=cv, n_jobs=-1)\n",
    "    r = mean(absolute(scores_r))\n",
    "    scores_auc = cross_val_score(clf, X, y, scoring='roc_auc', cv=cv, n_jobs=-1)\n",
    "    roc_auc = mean(absolute(scores_auc))\n",
    "\n",
    "    pred = clf.predict(X)\n",
    "    # a = accuracy_score(y,pred)\n",
    "    # p = precision_score(y,pred)\n",
    "    # r = recall_score(y,pred)\n",
    "    # roc_auc = roc_auc_score(y,pred)\n",
    "    # tn, fp, fn, tp = confusion_matrix(y, pred).ravel()\n",
    "    # fpr = fp/(fp+tn)\n",
    "\n",
    "    return a,p,r,roc_auc,fpr"
   ]
  },
  {
   "cell_type": "code",
   "execution_count": 9,
   "metadata": {},
   "outputs": [],
   "source": [
    "## list subgroups\n",
    "fair_metrics = pd.DataFrame(columns=['model', 'group', 'subgroup', 'Accuracy', 'Precision', 'Recall', 'AUC', 'FPR'])\n",
    "matrice = ['double_df_abi','double_df_keinAbi','double_df_boys','double_df_girls','double_df_deutsch','double_df_migration','double_df_buch0','double_df_buch1']\n",
    "group = ['abiEltern', 'abiEltern', 'gender', 'gender', 'erstsprache', 'erstsprache', 'buecher', 'buecher']\n",
    "subgroup = ['abi', 'keinAbi', 'boys', 'girls', 'deutsch', 'migration', 'buch0', 'buch1']"
   ]
  },
  {
   "attachments": {},
   "cell_type": "markdown",
   "metadata": {},
   "source": [
    "Decision Tree Classifier"
   ]
  },
  {
   "cell_type": "code",
   "execution_count": 10,
   "metadata": {},
   "outputs": [
    {
     "name": "stderr",
     "output_type": "stream",
     "text": [
      "c:\\Python310\\lib\\site-packages\\sklearn\\base.py:329: UserWarning: Trying to unpickle estimator DecisionTreeClassifier from version 0.24.0 when using version 1.0.2. This might lead to breaking code or invalid results. Use at your own risk. For more info please refer to:\n",
      "https://scikit-learn.org/stable/modules/model_persistence.html#security-maintainability-limitations\n",
      "  warnings.warn(\n"
     ]
    },
    {
     "name": "stdout",
     "output_type": "stream",
     "text": [
      "double_df_abi\n"
     ]
    },
    {
     "name": "stderr",
     "output_type": "stream",
     "text": [
      "c:\\Python310\\lib\\site-packages\\sklearn\\model_selection\\_validation.py:372: FitFailedWarning: \n",
      "1 fits failed out of a total of 5.\n",
      "The score on these train-test partitions for these parameters will be set to nan.\n",
      "If these failures are not expected, you can try to debug them by setting error_score='raise'.\n",
      "\n",
      "Below are more details about the failures:\n",
      "--------------------------------------------------------------------------------\n",
      "1 fits failed with the following error:\n",
      "Traceback (most recent call last):\n",
      "  File \"c:\\Python310\\lib\\site-packages\\sklearn\\model_selection\\_validation.py\", line 680, in _fit_and_score\n",
      "    estimator.fit(X_train, y_train, **fit_params)\n",
      "  File \"c:\\Python310\\lib\\site-packages\\sklearn\\tree\\_classes.py\", line 937, in fit\n",
      "    super().fit(\n",
      "  File \"c:\\Python310\\lib\\site-packages\\sklearn\\tree\\_classes.py\", line 165, in fit\n",
      "    X, y = self._validate_data(\n",
      "  File \"c:\\Python310\\lib\\site-packages\\sklearn\\base.py\", line 578, in _validate_data\n",
      "    X = check_array(X, **check_X_params)\n",
      "  File \"c:\\Python310\\lib\\site-packages\\sklearn\\utils\\validation.py\", line 746, in check_array\n",
      "    array = np.asarray(array, order=order, dtype=dtype)\n",
      "  File \"c:\\Python310\\lib\\site-packages\\pandas\\core\\generic.py\", line 2072, in __array__\n",
      "    return np.asarray(self._values, dtype=dtype)\n",
      "  File \"c:\\Python310\\lib\\site-packages\\pandas\\core\\frame.py\", line 918, in _values\n",
      "    return self.values\n",
      "  File \"c:\\Python310\\lib\\site-packages\\pandas\\core\\frame.py\", line 10877, in values\n",
      "    return self._mgr.as_array()\n",
      "  File \"c:\\Python310\\lib\\site-packages\\pandas\\core\\internals\\managers.py\", line 1589, in as_array\n",
      "    arr = self._interleave(dtype=dtype, na_value=na_value)\n",
      "  File \"c:\\Python310\\lib\\site-packages\\pandas\\core\\internals\\managers.py\", line 1628, in _interleave\n",
      "    result = np.empty(self.shape, dtype=dtype)\n",
      "numpy.core._exceptions._ArrayMemoryError: Unable to allocate 2.49 GiB for an array with shape (1077, 310701) and data type object\n",
      "\n",
      "  warnings.warn(some_fits_failed_message, FitFailedWarning)\n",
      "c:\\Python310\\lib\\site-packages\\sklearn\\model_selection\\_validation.py:372: FitFailedWarning: \n",
      "4 fits failed out of a total of 5.\n",
      "The score on these train-test partitions for these parameters will be set to nan.\n",
      "If these failures are not expected, you can try to debug them by setting error_score='raise'.\n",
      "\n",
      "Below are more details about the failures:\n",
      "--------------------------------------------------------------------------------\n",
      "1 fits failed with the following error:\n",
      "Traceback (most recent call last):\n",
      "  File \"c:\\Python310\\lib\\site-packages\\sklearn\\model_selection\\_validation.py\", line 680, in _fit_and_score\n",
      "    estimator.fit(X_train, y_train, **fit_params)\n",
      "  File \"c:\\Python310\\lib\\site-packages\\sklearn\\tree\\_classes.py\", line 937, in fit\n",
      "    super().fit(\n",
      "  File \"c:\\Python310\\lib\\site-packages\\sklearn\\tree\\_classes.py\", line 165, in fit\n",
      "    X, y = self._validate_data(\n",
      "  File \"c:\\Python310\\lib\\site-packages\\sklearn\\base.py\", line 578, in _validate_data\n",
      "    X = check_array(X, **check_X_params)\n",
      "  File \"c:\\Python310\\lib\\site-packages\\sklearn\\utils\\validation.py\", line 746, in check_array\n",
      "    array = np.asarray(array, order=order, dtype=dtype)\n",
      "  File \"c:\\Python310\\lib\\site-packages\\pandas\\core\\generic.py\", line 2072, in __array__\n",
      "    return np.asarray(self._values, dtype=dtype)\n",
      "  File \"c:\\Python310\\lib\\site-packages\\pandas\\core\\frame.py\", line 918, in _values\n",
      "    return self.values\n",
      "  File \"c:\\Python310\\lib\\site-packages\\pandas\\core\\frame.py\", line 10877, in values\n",
      "    return self._mgr.as_array()\n",
      "  File \"c:\\Python310\\lib\\site-packages\\pandas\\core\\internals\\managers.py\", line 1589, in as_array\n",
      "    arr = self._interleave(dtype=dtype, na_value=na_value)\n",
      "  File \"c:\\Python310\\lib\\site-packages\\pandas\\core\\internals\\managers.py\", line 1636, in _interleave\n",
      "    arr = blk.get_values(dtype)\n",
      "  File \"c:\\Python310\\lib\\site-packages\\pandas\\core\\internals\\blocks.py\", line 228, in get_values\n",
      "    return self.values.astype(_dtype_obj)\n",
      "numpy.core._exceptions._ArrayMemoryError: Unable to allocate 2.44 GiB for an array with shape (1056, 310700) and data type object\n",
      "\n",
      "--------------------------------------------------------------------------------\n",
      "3 fits failed with the following error:\n",
      "Traceback (most recent call last):\n",
      "  File \"c:\\Python310\\lib\\site-packages\\sklearn\\model_selection\\_validation.py\", line 680, in _fit_and_score\n",
      "    estimator.fit(X_train, y_train, **fit_params)\n",
      "  File \"c:\\Python310\\lib\\site-packages\\sklearn\\tree\\_classes.py\", line 937, in fit\n",
      "    super().fit(\n",
      "  File \"c:\\Python310\\lib\\site-packages\\sklearn\\tree\\_classes.py\", line 165, in fit\n",
      "    X, y = self._validate_data(\n",
      "  File \"c:\\Python310\\lib\\site-packages\\sklearn\\base.py\", line 578, in _validate_data\n",
      "    X = check_array(X, **check_X_params)\n",
      "  File \"c:\\Python310\\lib\\site-packages\\sklearn\\utils\\validation.py\", line 746, in check_array\n",
      "    array = np.asarray(array, order=order, dtype=dtype)\n",
      "  File \"c:\\Python310\\lib\\site-packages\\pandas\\core\\generic.py\", line 2072, in __array__\n",
      "    return np.asarray(self._values, dtype=dtype)\n",
      "  File \"c:\\Python310\\lib\\site-packages\\pandas\\core\\frame.py\", line 918, in _values\n",
      "    return self.values\n",
      "  File \"c:\\Python310\\lib\\site-packages\\pandas\\core\\frame.py\", line 10877, in values\n",
      "    return self._mgr.as_array()\n",
      "  File \"c:\\Python310\\lib\\site-packages\\pandas\\core\\internals\\managers.py\", line 1589, in as_array\n",
      "    arr = self._interleave(dtype=dtype, na_value=na_value)\n",
      "  File \"c:\\Python310\\lib\\site-packages\\pandas\\core\\internals\\managers.py\", line 1636, in _interleave\n",
      "    arr = blk.get_values(dtype)\n",
      "  File \"c:\\Python310\\lib\\site-packages\\pandas\\core\\internals\\blocks.py\", line 228, in get_values\n",
      "    return self.values.astype(_dtype_obj)\n",
      "numpy.core._exceptions._ArrayMemoryError: Unable to allocate 2.44 GiB for an array with shape (1056, 310701) and data type object\n",
      "\n",
      "  warnings.warn(some_fits_failed_message, FitFailedWarning)\n",
      "c:\\Python310\\lib\\site-packages\\sklearn\\model_selection\\_validation.py:372: FitFailedWarning: \n",
      "2 fits failed out of a total of 5.\n",
      "The score on these train-test partitions for these parameters will be set to nan.\n",
      "If these failures are not expected, you can try to debug them by setting error_score='raise'.\n",
      "\n",
      "Below are more details about the failures:\n",
      "--------------------------------------------------------------------------------\n",
      "1 fits failed with the following error:\n",
      "Traceback (most recent call last):\n",
      "  File \"c:\\Python310\\lib\\site-packages\\sklearn\\model_selection\\_validation.py\", line 680, in _fit_and_score\n",
      "    estimator.fit(X_train, y_train, **fit_params)\n",
      "  File \"c:\\Python310\\lib\\site-packages\\sklearn\\tree\\_classes.py\", line 937, in fit\n",
      "    super().fit(\n",
      "  File \"c:\\Python310\\lib\\site-packages\\sklearn\\tree\\_classes.py\", line 165, in fit\n",
      "    X, y = self._validate_data(\n",
      "  File \"c:\\Python310\\lib\\site-packages\\sklearn\\base.py\", line 578, in _validate_data\n",
      "    X = check_array(X, **check_X_params)\n",
      "  File \"c:\\Python310\\lib\\site-packages\\sklearn\\utils\\validation.py\", line 746, in check_array\n",
      "    array = np.asarray(array, order=order, dtype=dtype)\n",
      "  File \"c:\\Python310\\lib\\site-packages\\pandas\\core\\generic.py\", line 2072, in __array__\n",
      "    return np.asarray(self._values, dtype=dtype)\n",
      "  File \"c:\\Python310\\lib\\site-packages\\pandas\\core\\frame.py\", line 918, in _values\n",
      "    return self.values\n",
      "  File \"c:\\Python310\\lib\\site-packages\\pandas\\core\\frame.py\", line 10877, in values\n",
      "    return self._mgr.as_array()\n",
      "  File \"c:\\Python310\\lib\\site-packages\\pandas\\core\\internals\\managers.py\", line 1589, in as_array\n",
      "    arr = self._interleave(dtype=dtype, na_value=na_value)\n",
      "  File \"c:\\Python310\\lib\\site-packages\\pandas\\core\\internals\\managers.py\", line 1628, in _interleave\n",
      "    result = np.empty(self.shape, dtype=dtype)\n",
      "numpy.core._exceptions._ArrayMemoryError: Unable to allocate 2.49 GiB for an array with shape (1077, 310700) and data type object\n",
      "\n",
      "--------------------------------------------------------------------------------\n",
      "1 fits failed with the following error:\n",
      "Traceback (most recent call last):\n",
      "  File \"c:\\Python310\\lib\\site-packages\\sklearn\\model_selection\\_validation.py\", line 680, in _fit_and_score\n",
      "    estimator.fit(X_train, y_train, **fit_params)\n",
      "  File \"c:\\Python310\\lib\\site-packages\\sklearn\\tree\\_classes.py\", line 937, in fit\n",
      "    super().fit(\n",
      "  File \"c:\\Python310\\lib\\site-packages\\sklearn\\tree\\_classes.py\", line 165, in fit\n",
      "    X, y = self._validate_data(\n",
      "  File \"c:\\Python310\\lib\\site-packages\\sklearn\\base.py\", line 578, in _validate_data\n",
      "    X = check_array(X, **check_X_params)\n",
      "  File \"c:\\Python310\\lib\\site-packages\\sklearn\\utils\\validation.py\", line 746, in check_array\n",
      "    array = np.asarray(array, order=order, dtype=dtype)\n",
      "  File \"c:\\Python310\\lib\\site-packages\\pandas\\core\\generic.py\", line 2072, in __array__\n",
      "    return np.asarray(self._values, dtype=dtype)\n",
      "  File \"c:\\Python310\\lib\\site-packages\\pandas\\core\\frame.py\", line 918, in _values\n",
      "    return self.values\n",
      "  File \"c:\\Python310\\lib\\site-packages\\pandas\\core\\frame.py\", line 10877, in values\n",
      "    return self._mgr.as_array()\n",
      "  File \"c:\\Python310\\lib\\site-packages\\pandas\\core\\internals\\managers.py\", line 1589, in as_array\n",
      "    arr = self._interleave(dtype=dtype, na_value=na_value)\n",
      "  File \"c:\\Python310\\lib\\site-packages\\pandas\\core\\internals\\managers.py\", line 1628, in _interleave\n",
      "    result = np.empty(self.shape, dtype=dtype)\n",
      "numpy.core._exceptions._ArrayMemoryError: Unable to allocate 2.49 GiB for an array with shape (1077, 310701) and data type object\n",
      "\n",
      "  warnings.warn(some_fits_failed_message, FitFailedWarning)\n",
      "c:\\Python310\\lib\\site-packages\\sklearn\\utils\\validation.py:1688: FutureWarning: Feature names only support names that are all strings. Got feature names with dtypes: ['int', 'str']. An error will be raised in 1.2.\n",
      "  warnings.warn(\n",
      "C:\\Users\\Nathalie\\AppData\\Local\\Temp\\ipykernel_19420\\740705286.py:17: FutureWarning: The frame.append method is deprecated and will be removed from pandas in a future version. Use pandas.concat instead.\n",
      "  fair_metrics = fair_metrics.append({'model':'DTE','group':group,'subgroup':subgroup,'Accuracy':a,'Precision': p, 'Recall':r, 'AUC':roc_auc, 'FPR':fpr}, ignore_index=True)\n"
     ]
    },
    {
     "name": "stdout",
     "output_type": "stream",
     "text": [
      "double_df_keinAbi\n"
     ]
    },
    {
     "name": "stderr",
     "output_type": "stream",
     "text": [
      "c:\\Python310\\lib\\site-packages\\sklearn\\utils\\validation.py:1688: FutureWarning: Feature names only support names that are all strings. Got feature names with dtypes: ['int', 'str']. An error will be raised in 1.2.\n",
      "  warnings.warn(\n",
      "C:\\Users\\Nathalie\\AppData\\Local\\Temp\\ipykernel_19420\\740705286.py:17: FutureWarning: The frame.append method is deprecated and will be removed from pandas in a future version. Use pandas.concat instead.\n",
      "  fair_metrics = fair_metrics.append({'model':'DTE','group':group,'subgroup':subgroup,'Accuracy':a,'Precision': p, 'Recall':r, 'AUC':roc_auc, 'FPR':fpr}, ignore_index=True)\n"
     ]
    },
    {
     "name": "stdout",
     "output_type": "stream",
     "text": [
      "double_df_boys\n"
     ]
    },
    {
     "name": "stderr",
     "output_type": "stream",
     "text": [
      "c:\\Python310\\lib\\site-packages\\sklearn\\model_selection\\_validation.py:372: FitFailedWarning: \n",
      "3 fits failed out of a total of 5.\n",
      "The score on these train-test partitions for these parameters will be set to nan.\n",
      "If these failures are not expected, you can try to debug them by setting error_score='raise'.\n",
      "\n",
      "Below are more details about the failures:\n",
      "--------------------------------------------------------------------------------\n",
      "3 fits failed with the following error:\n",
      "Traceback (most recent call last):\n",
      "  File \"c:\\Python310\\lib\\site-packages\\sklearn\\model_selection\\_validation.py\", line 680, in _fit_and_score\n",
      "    estimator.fit(X_train, y_train, **fit_params)\n",
      "  File \"c:\\Python310\\lib\\site-packages\\sklearn\\tree\\_classes.py\", line 937, in fit\n",
      "    super().fit(\n",
      "  File \"c:\\Python310\\lib\\site-packages\\sklearn\\tree\\_classes.py\", line 165, in fit\n",
      "    X, y = self._validate_data(\n",
      "  File \"c:\\Python310\\lib\\site-packages\\sklearn\\base.py\", line 578, in _validate_data\n",
      "    X = check_array(X, **check_X_params)\n",
      "  File \"c:\\Python310\\lib\\site-packages\\sklearn\\utils\\validation.py\", line 746, in check_array\n",
      "    array = np.asarray(array, order=order, dtype=dtype)\n",
      "  File \"c:\\Python310\\lib\\site-packages\\pandas\\core\\generic.py\", line 2072, in __array__\n",
      "    return np.asarray(self._values, dtype=dtype)\n",
      "  File \"c:\\Python310\\lib\\site-packages\\pandas\\core\\frame.py\", line 918, in _values\n",
      "    return self.values\n",
      "  File \"c:\\Python310\\lib\\site-packages\\pandas\\core\\frame.py\", line 10877, in values\n",
      "    return self._mgr.as_array()\n",
      "  File \"c:\\Python310\\lib\\site-packages\\pandas\\core\\internals\\managers.py\", line 1589, in as_array\n",
      "    arr = self._interleave(dtype=dtype, na_value=na_value)\n",
      "  File \"c:\\Python310\\lib\\site-packages\\pandas\\core\\internals\\managers.py\", line 1636, in _interleave\n",
      "    arr = blk.get_values(dtype)\n",
      "  File \"c:\\Python310\\lib\\site-packages\\pandas\\core\\internals\\blocks.py\", line 228, in get_values\n",
      "    return self.values.astype(_dtype_obj)\n",
      "numpy.core._exceptions._ArrayMemoryError: Unable to allocate 2.64 GiB for an array with shape (1056, 335446) and data type object\n",
      "\n",
      "  warnings.warn(some_fits_failed_message, FitFailedWarning)\n",
      "c:\\Python310\\lib\\site-packages\\sklearn\\model_selection\\_validation.py:372: FitFailedWarning: \n",
      "3 fits failed out of a total of 5.\n",
      "The score on these train-test partitions for these parameters will be set to nan.\n",
      "If these failures are not expected, you can try to debug them by setting error_score='raise'.\n",
      "\n",
      "Below are more details about the failures:\n",
      "--------------------------------------------------------------------------------\n",
      "2 fits failed with the following error:\n",
      "Traceback (most recent call last):\n",
      "  File \"c:\\Python310\\lib\\site-packages\\sklearn\\model_selection\\_validation.py\", line 680, in _fit_and_score\n",
      "    estimator.fit(X_train, y_train, **fit_params)\n",
      "  File \"c:\\Python310\\lib\\site-packages\\sklearn\\tree\\_classes.py\", line 937, in fit\n",
      "    super().fit(\n",
      "  File \"c:\\Python310\\lib\\site-packages\\sklearn\\tree\\_classes.py\", line 165, in fit\n",
      "    X, y = self._validate_data(\n",
      "  File \"c:\\Python310\\lib\\site-packages\\sklearn\\base.py\", line 578, in _validate_data\n",
      "    X = check_array(X, **check_X_params)\n",
      "  File \"c:\\Python310\\lib\\site-packages\\sklearn\\utils\\validation.py\", line 746, in check_array\n",
      "    array = np.asarray(array, order=order, dtype=dtype)\n",
      "  File \"c:\\Python310\\lib\\site-packages\\pandas\\core\\generic.py\", line 2072, in __array__\n",
      "    return np.asarray(self._values, dtype=dtype)\n",
      "  File \"c:\\Python310\\lib\\site-packages\\pandas\\core\\frame.py\", line 918, in _values\n",
      "    return self.values\n",
      "  File \"c:\\Python310\\lib\\site-packages\\pandas\\core\\frame.py\", line 10877, in values\n",
      "    return self._mgr.as_array()\n",
      "  File \"c:\\Python310\\lib\\site-packages\\pandas\\core\\internals\\managers.py\", line 1589, in as_array\n",
      "    arr = self._interleave(dtype=dtype, na_value=na_value)\n",
      "  File \"c:\\Python310\\lib\\site-packages\\pandas\\core\\internals\\managers.py\", line 1636, in _interleave\n",
      "    arr = blk.get_values(dtype)\n",
      "  File \"c:\\Python310\\lib\\site-packages\\pandas\\core\\internals\\blocks.py\", line 228, in get_values\n",
      "    return self.values.astype(_dtype_obj)\n",
      "numpy.core._exceptions._ArrayMemoryError: Unable to allocate 2.64 GiB for an array with shape (1056, 335445) and data type object\n",
      "\n",
      "--------------------------------------------------------------------------------\n",
      "1 fits failed with the following error:\n",
      "Traceback (most recent call last):\n",
      "  File \"c:\\Python310\\lib\\site-packages\\sklearn\\model_selection\\_validation.py\", line 680, in _fit_and_score\n",
      "    estimator.fit(X_train, y_train, **fit_params)\n",
      "  File \"c:\\Python310\\lib\\site-packages\\sklearn\\tree\\_classes.py\", line 937, in fit\n",
      "    super().fit(\n",
      "  File \"c:\\Python310\\lib\\site-packages\\sklearn\\tree\\_classes.py\", line 165, in fit\n",
      "    X, y = self._validate_data(\n",
      "  File \"c:\\Python310\\lib\\site-packages\\sklearn\\base.py\", line 578, in _validate_data\n",
      "    X = check_array(X, **check_X_params)\n",
      "  File \"c:\\Python310\\lib\\site-packages\\sklearn\\utils\\validation.py\", line 746, in check_array\n",
      "    array = np.asarray(array, order=order, dtype=dtype)\n",
      "  File \"c:\\Python310\\lib\\site-packages\\pandas\\core\\generic.py\", line 2072, in __array__\n",
      "    return np.asarray(self._values, dtype=dtype)\n",
      "  File \"c:\\Python310\\lib\\site-packages\\pandas\\core\\frame.py\", line 918, in _values\n",
      "    return self.values\n",
      "  File \"c:\\Python310\\lib\\site-packages\\pandas\\core\\frame.py\", line 10877, in values\n",
      "    return self._mgr.as_array()\n",
      "  File \"c:\\Python310\\lib\\site-packages\\pandas\\core\\internals\\managers.py\", line 1589, in as_array\n",
      "    arr = self._interleave(dtype=dtype, na_value=na_value)\n",
      "  File \"c:\\Python310\\lib\\site-packages\\pandas\\core\\internals\\managers.py\", line 1636, in _interleave\n",
      "    arr = blk.get_values(dtype)\n",
      "  File \"c:\\Python310\\lib\\site-packages\\pandas\\core\\internals\\blocks.py\", line 228, in get_values\n",
      "    return self.values.astype(_dtype_obj)\n",
      "numpy.core._exceptions._ArrayMemoryError: Unable to allocate 2.64 GiB for an array with shape (1056, 335446) and data type object\n",
      "\n",
      "  warnings.warn(some_fits_failed_message, FitFailedWarning)\n",
      "c:\\Python310\\lib\\site-packages\\sklearn\\model_selection\\_validation.py:372: FitFailedWarning: \n",
      "3 fits failed out of a total of 5.\n",
      "The score on these train-test partitions for these parameters will be set to nan.\n",
      "If these failures are not expected, you can try to debug them by setting error_score='raise'.\n",
      "\n",
      "Below are more details about the failures:\n",
      "--------------------------------------------------------------------------------\n",
      "1 fits failed with the following error:\n",
      "Traceback (most recent call last):\n",
      "  File \"c:\\Python310\\lib\\site-packages\\sklearn\\model_selection\\_validation.py\", line 680, in _fit_and_score\n",
      "    estimator.fit(X_train, y_train, **fit_params)\n",
      "  File \"c:\\Python310\\lib\\site-packages\\sklearn\\tree\\_classes.py\", line 937, in fit\n",
      "    super().fit(\n",
      "  File \"c:\\Python310\\lib\\site-packages\\sklearn\\tree\\_classes.py\", line 165, in fit\n",
      "    X, y = self._validate_data(\n",
      "  File \"c:\\Python310\\lib\\site-packages\\sklearn\\base.py\", line 578, in _validate_data\n",
      "    X = check_array(X, **check_X_params)\n",
      "  File \"c:\\Python310\\lib\\site-packages\\sklearn\\utils\\validation.py\", line 746, in check_array\n",
      "    array = np.asarray(array, order=order, dtype=dtype)\n",
      "  File \"c:\\Python310\\lib\\site-packages\\pandas\\core\\generic.py\", line 2072, in __array__\n",
      "    return np.asarray(self._values, dtype=dtype)\n",
      "  File \"c:\\Python310\\lib\\site-packages\\pandas\\core\\frame.py\", line 918, in _values\n",
      "    return self.values\n",
      "  File \"c:\\Python310\\lib\\site-packages\\pandas\\core\\frame.py\", line 10877, in values\n",
      "    return self._mgr.as_array()\n",
      "  File \"c:\\Python310\\lib\\site-packages\\pandas\\core\\internals\\managers.py\", line 1589, in as_array\n",
      "    arr = self._interleave(dtype=dtype, na_value=na_value)\n",
      "  File \"c:\\Python310\\lib\\site-packages\\pandas\\core\\internals\\managers.py\", line 1636, in _interleave\n",
      "    arr = blk.get_values(dtype)\n",
      "  File \"c:\\Python310\\lib\\site-packages\\pandas\\core\\internals\\blocks.py\", line 228, in get_values\n",
      "    return self.values.astype(_dtype_obj)\n",
      "numpy.core._exceptions._ArrayMemoryError: Unable to allocate 2.64 GiB for an array with shape (1056, 335445) and data type object\n",
      "\n",
      "--------------------------------------------------------------------------------\n",
      "2 fits failed with the following error:\n",
      "Traceback (most recent call last):\n",
      "  File \"c:\\Python310\\lib\\site-packages\\sklearn\\model_selection\\_validation.py\", line 680, in _fit_and_score\n",
      "    estimator.fit(X_train, y_train, **fit_params)\n",
      "  File \"c:\\Python310\\lib\\site-packages\\sklearn\\tree\\_classes.py\", line 937, in fit\n",
      "    super().fit(\n",
      "  File \"c:\\Python310\\lib\\site-packages\\sklearn\\tree\\_classes.py\", line 165, in fit\n",
      "    X, y = self._validate_data(\n",
      "  File \"c:\\Python310\\lib\\site-packages\\sklearn\\base.py\", line 578, in _validate_data\n",
      "    X = check_array(X, **check_X_params)\n",
      "  File \"c:\\Python310\\lib\\site-packages\\sklearn\\utils\\validation.py\", line 746, in check_array\n",
      "    array = np.asarray(array, order=order, dtype=dtype)\n",
      "  File \"c:\\Python310\\lib\\site-packages\\pandas\\core\\generic.py\", line 2072, in __array__\n",
      "    return np.asarray(self._values, dtype=dtype)\n",
      "  File \"c:\\Python310\\lib\\site-packages\\pandas\\core\\frame.py\", line 918, in _values\n",
      "    return self.values\n",
      "  File \"c:\\Python310\\lib\\site-packages\\pandas\\core\\frame.py\", line 10877, in values\n",
      "    return self._mgr.as_array()\n",
      "  File \"c:\\Python310\\lib\\site-packages\\pandas\\core\\internals\\managers.py\", line 1589, in as_array\n",
      "    arr = self._interleave(dtype=dtype, na_value=na_value)\n",
      "  File \"c:\\Python310\\lib\\site-packages\\pandas\\core\\internals\\managers.py\", line 1636, in _interleave\n",
      "    arr = blk.get_values(dtype)\n",
      "  File \"c:\\Python310\\lib\\site-packages\\pandas\\core\\internals\\blocks.py\", line 228, in get_values\n",
      "    return self.values.astype(_dtype_obj)\n",
      "numpy.core._exceptions._ArrayMemoryError: Unable to allocate 2.64 GiB for an array with shape (1056, 335446) and data type object\n",
      "\n",
      "  warnings.warn(some_fits_failed_message, FitFailedWarning)\n",
      "c:\\Python310\\lib\\site-packages\\sklearn\\model_selection\\_validation.py:372: FitFailedWarning: \n",
      "3 fits failed out of a total of 5.\n",
      "The score on these train-test partitions for these parameters will be set to nan.\n",
      "If these failures are not expected, you can try to debug them by setting error_score='raise'.\n",
      "\n",
      "Below are more details about the failures:\n",
      "--------------------------------------------------------------------------------\n",
      "1 fits failed with the following error:\n",
      "Traceback (most recent call last):\n",
      "  File \"c:\\Python310\\lib\\site-packages\\sklearn\\model_selection\\_validation.py\", line 680, in _fit_and_score\n",
      "    estimator.fit(X_train, y_train, **fit_params)\n",
      "  File \"c:\\Python310\\lib\\site-packages\\sklearn\\tree\\_classes.py\", line 937, in fit\n",
      "    super().fit(\n",
      "  File \"c:\\Python310\\lib\\site-packages\\sklearn\\tree\\_classes.py\", line 165, in fit\n",
      "    X, y = self._validate_data(\n",
      "  File \"c:\\Python310\\lib\\site-packages\\sklearn\\base.py\", line 578, in _validate_data\n",
      "    X = check_array(X, **check_X_params)\n",
      "  File \"c:\\Python310\\lib\\site-packages\\sklearn\\utils\\validation.py\", line 746, in check_array\n",
      "    array = np.asarray(array, order=order, dtype=dtype)\n",
      "  File \"c:\\Python310\\lib\\site-packages\\pandas\\core\\generic.py\", line 2072, in __array__\n",
      "    return np.asarray(self._values, dtype=dtype)\n",
      "  File \"c:\\Python310\\lib\\site-packages\\pandas\\core\\frame.py\", line 918, in _values\n",
      "    return self.values\n",
      "  File \"c:\\Python310\\lib\\site-packages\\pandas\\core\\frame.py\", line 10877, in values\n",
      "    return self._mgr.as_array()\n",
      "  File \"c:\\Python310\\lib\\site-packages\\pandas\\core\\internals\\managers.py\", line 1589, in as_array\n",
      "    arr = self._interleave(dtype=dtype, na_value=na_value)\n",
      "  File \"c:\\Python310\\lib\\site-packages\\pandas\\core\\internals\\managers.py\", line 1636, in _interleave\n",
      "    arr = blk.get_values(dtype)\n",
      "  File \"c:\\Python310\\lib\\site-packages\\pandas\\core\\internals\\blocks.py\", line 228, in get_values\n",
      "    return self.values.astype(_dtype_obj)\n",
      "numpy.core._exceptions._ArrayMemoryError: Unable to allocate 2.64 GiB for an array with shape (1056, 335445) and data type object\n",
      "\n",
      "--------------------------------------------------------------------------------\n",
      "1 fits failed with the following error:\n",
      "Traceback (most recent call last):\n",
      "  File \"c:\\Python310\\lib\\site-packages\\sklearn\\model_selection\\_validation.py\", line 680, in _fit_and_score\n",
      "    estimator.fit(X_train, y_train, **fit_params)\n",
      "  File \"c:\\Python310\\lib\\site-packages\\sklearn\\tree\\_classes.py\", line 937, in fit\n",
      "    super().fit(\n",
      "  File \"c:\\Python310\\lib\\site-packages\\sklearn\\tree\\_classes.py\", line 165, in fit\n",
      "    X, y = self._validate_data(\n",
      "  File \"c:\\Python310\\lib\\site-packages\\sklearn\\base.py\", line 578, in _validate_data\n",
      "    X = check_array(X, **check_X_params)\n",
      "  File \"c:\\Python310\\lib\\site-packages\\sklearn\\utils\\validation.py\", line 746, in check_array\n",
      "    array = np.asarray(array, order=order, dtype=dtype)\n",
      "  File \"c:\\Python310\\lib\\site-packages\\pandas\\core\\generic.py\", line 2072, in __array__\n",
      "    return np.asarray(self._values, dtype=dtype)\n",
      "  File \"c:\\Python310\\lib\\site-packages\\pandas\\core\\frame.py\", line 918, in _values\n",
      "    return self.values\n",
      "  File \"c:\\Python310\\lib\\site-packages\\pandas\\core\\frame.py\", line 10877, in values\n",
      "    return self._mgr.as_array()\n",
      "  File \"c:\\Python310\\lib\\site-packages\\pandas\\core\\internals\\managers.py\", line 1589, in as_array\n",
      "    arr = self._interleave(dtype=dtype, na_value=na_value)\n",
      "  File \"c:\\Python310\\lib\\site-packages\\pandas\\core\\internals\\managers.py\", line 1636, in _interleave\n",
      "    arr = blk.get_values(dtype)\n",
      "  File \"c:\\Python310\\lib\\site-packages\\pandas\\core\\internals\\blocks.py\", line 228, in get_values\n",
      "    return self.values.astype(_dtype_obj)\n",
      "numpy.core._exceptions._ArrayMemoryError: Unable to allocate 2.64 GiB for an array with shape (1056, 335446) and data type object\n",
      "\n",
      "--------------------------------------------------------------------------------\n",
      "1 fits failed with the following error:\n",
      "Traceback (most recent call last):\n",
      "  File \"c:\\Python310\\lib\\site-packages\\sklearn\\model_selection\\_validation.py\", line 680, in _fit_and_score\n",
      "    estimator.fit(X_train, y_train, **fit_params)\n",
      "  File \"c:\\Python310\\lib\\site-packages\\sklearn\\tree\\_classes.py\", line 937, in fit\n",
      "    super().fit(\n",
      "  File \"c:\\Python310\\lib\\site-packages\\sklearn\\tree\\_classes.py\", line 165, in fit\n",
      "    X, y = self._validate_data(\n",
      "  File \"c:\\Python310\\lib\\site-packages\\sklearn\\base.py\", line 578, in _validate_data\n",
      "    X = check_array(X, **check_X_params)\n",
      "  File \"c:\\Python310\\lib\\site-packages\\sklearn\\utils\\validation.py\", line 746, in check_array\n",
      "    array = np.asarray(array, order=order, dtype=dtype)\n",
      "  File \"c:\\Python310\\lib\\site-packages\\pandas\\core\\generic.py\", line 2072, in __array__\n",
      "    return np.asarray(self._values, dtype=dtype)\n",
      "  File \"c:\\Python310\\lib\\site-packages\\pandas\\core\\frame.py\", line 918, in _values\n",
      "    return self.values\n",
      "  File \"c:\\Python310\\lib\\site-packages\\pandas\\core\\frame.py\", line 10877, in values\n",
      "    return self._mgr.as_array()\n",
      "  File \"c:\\Python310\\lib\\site-packages\\pandas\\core\\internals\\managers.py\", line 1589, in as_array\n",
      "    arr = self._interleave(dtype=dtype, na_value=na_value)\n",
      "  File \"c:\\Python310\\lib\\site-packages\\pandas\\core\\internals\\managers.py\", line 1628, in _interleave\n",
      "    result = np.empty(self.shape, dtype=dtype)\n",
      "numpy.core._exceptions._ArrayMemoryError: Unable to allocate 2.69 GiB for an array with shape (1077, 335446) and data type object\n",
      "\n",
      "  warnings.warn(some_fits_failed_message, FitFailedWarning)\n",
      "c:\\Python310\\lib\\site-packages\\sklearn\\utils\\validation.py:1688: FutureWarning: Feature names only support names that are all strings. Got feature names with dtypes: ['int', 'str']. An error will be raised in 1.2.\n",
      "  warnings.warn(\n",
      "C:\\Users\\Nathalie\\AppData\\Local\\Temp\\ipykernel_19420\\740705286.py:17: FutureWarning: The frame.append method is deprecated and will be removed from pandas in a future version. Use pandas.concat instead.\n",
      "  fair_metrics = fair_metrics.append({'model':'DTE','group':group,'subgroup':subgroup,'Accuracy':a,'Precision': p, 'Recall':r, 'AUC':roc_auc, 'FPR':fpr}, ignore_index=True)\n"
     ]
    },
    {
     "name": "stdout",
     "output_type": "stream",
     "text": [
      "double_df_girls\n"
     ]
    },
    {
     "name": "stderr",
     "output_type": "stream",
     "text": [
      "c:\\Python310\\lib\\site-packages\\sklearn\\model_selection\\_validation.py:372: FitFailedWarning: \n",
      "4 fits failed out of a total of 5.\n",
      "The score on these train-test partitions for these parameters will be set to nan.\n",
      "If these failures are not expected, you can try to debug them by setting error_score='raise'.\n",
      "\n",
      "Below are more details about the failures:\n",
      "--------------------------------------------------------------------------------\n",
      "3 fits failed with the following error:\n",
      "Traceback (most recent call last):\n",
      "  File \"c:\\Python310\\lib\\site-packages\\sklearn\\model_selection\\_validation.py\", line 680, in _fit_and_score\n",
      "    estimator.fit(X_train, y_train, **fit_params)\n",
      "  File \"c:\\Python310\\lib\\site-packages\\sklearn\\tree\\_classes.py\", line 937, in fit\n",
      "    super().fit(\n",
      "  File \"c:\\Python310\\lib\\site-packages\\sklearn\\tree\\_classes.py\", line 165, in fit\n",
      "    X, y = self._validate_data(\n",
      "  File \"c:\\Python310\\lib\\site-packages\\sklearn\\base.py\", line 578, in _validate_data\n",
      "    X = check_array(X, **check_X_params)\n",
      "  File \"c:\\Python310\\lib\\site-packages\\sklearn\\utils\\validation.py\", line 746, in check_array\n",
      "    array = np.asarray(array, order=order, dtype=dtype)\n",
      "  File \"c:\\Python310\\lib\\site-packages\\pandas\\core\\generic.py\", line 2072, in __array__\n",
      "    return np.asarray(self._values, dtype=dtype)\n",
      "  File \"c:\\Python310\\lib\\site-packages\\pandas\\core\\frame.py\", line 918, in _values\n",
      "    return self.values\n",
      "  File \"c:\\Python310\\lib\\site-packages\\pandas\\core\\frame.py\", line 10877, in values\n",
      "    return self._mgr.as_array()\n",
      "  File \"c:\\Python310\\lib\\site-packages\\pandas\\core\\internals\\managers.py\", line 1589, in as_array\n",
      "    arr = self._interleave(dtype=dtype, na_value=na_value)\n",
      "  File \"c:\\Python310\\lib\\site-packages\\pandas\\core\\internals\\managers.py\", line 1636, in _interleave\n",
      "    arr = blk.get_values(dtype)\n",
      "  File \"c:\\Python310\\lib\\site-packages\\pandas\\core\\internals\\blocks.py\", line 228, in get_values\n",
      "    return self.values.astype(_dtype_obj)\n",
      "numpy.core._exceptions._ArrayMemoryError: Unable to allocate 2.78 GiB for an array with shape (1056, 353191) and data type object\n",
      "\n",
      "--------------------------------------------------------------------------------\n",
      "1 fits failed with the following error:\n",
      "Traceback (most recent call last):\n",
      "  File \"c:\\Python310\\lib\\site-packages\\sklearn\\model_selection\\_validation.py\", line 680, in _fit_and_score\n",
      "    estimator.fit(X_train, y_train, **fit_params)\n",
      "  File \"c:\\Python310\\lib\\site-packages\\sklearn\\tree\\_classes.py\", line 937, in fit\n",
      "    super().fit(\n",
      "  File \"c:\\Python310\\lib\\site-packages\\sklearn\\tree\\_classes.py\", line 165, in fit\n",
      "    X, y = self._validate_data(\n",
      "  File \"c:\\Python310\\lib\\site-packages\\sklearn\\base.py\", line 578, in _validate_data\n",
      "    X = check_array(X, **check_X_params)\n",
      "  File \"c:\\Python310\\lib\\site-packages\\sklearn\\utils\\validation.py\", line 746, in check_array\n",
      "    array = np.asarray(array, order=order, dtype=dtype)\n",
      "  File \"c:\\Python310\\lib\\site-packages\\pandas\\core\\generic.py\", line 2072, in __array__\n",
      "    return np.asarray(self._values, dtype=dtype)\n",
      "  File \"c:\\Python310\\lib\\site-packages\\pandas\\core\\frame.py\", line 918, in _values\n",
      "    return self.values\n",
      "  File \"c:\\Python310\\lib\\site-packages\\pandas\\core\\frame.py\", line 10877, in values\n",
      "    return self._mgr.as_array()\n",
      "  File \"c:\\Python310\\lib\\site-packages\\pandas\\core\\internals\\managers.py\", line 1589, in as_array\n",
      "    arr = self._interleave(dtype=dtype, na_value=na_value)\n",
      "  File \"c:\\Python310\\lib\\site-packages\\pandas\\core\\internals\\managers.py\", line 1628, in _interleave\n",
      "    result = np.empty(self.shape, dtype=dtype)\n",
      "numpy.core._exceptions._ArrayMemoryError: Unable to allocate 2.83 GiB for an array with shape (1077, 353191) and data type object\n",
      "\n",
      "  warnings.warn(some_fits_failed_message, FitFailedWarning)\n",
      "c:\\Python310\\lib\\site-packages\\sklearn\\model_selection\\_validation.py:372: FitFailedWarning: \n",
      "2 fits failed out of a total of 5.\n",
      "The score on these train-test partitions for these parameters will be set to nan.\n",
      "If these failures are not expected, you can try to debug them by setting error_score='raise'.\n",
      "\n",
      "Below are more details about the failures:\n",
      "--------------------------------------------------------------------------------\n",
      "1 fits failed with the following error:\n",
      "Traceback (most recent call last):\n",
      "  File \"c:\\Python310\\lib\\site-packages\\sklearn\\model_selection\\_validation.py\", line 680, in _fit_and_score\n",
      "    estimator.fit(X_train, y_train, **fit_params)\n",
      "  File \"c:\\Python310\\lib\\site-packages\\sklearn\\tree\\_classes.py\", line 937, in fit\n",
      "    super().fit(\n",
      "  File \"c:\\Python310\\lib\\site-packages\\sklearn\\tree\\_classes.py\", line 165, in fit\n",
      "    X, y = self._validate_data(\n",
      "  File \"c:\\Python310\\lib\\site-packages\\sklearn\\base.py\", line 578, in _validate_data\n",
      "    X = check_array(X, **check_X_params)\n",
      "  File \"c:\\Python310\\lib\\site-packages\\sklearn\\utils\\validation.py\", line 746, in check_array\n",
      "    array = np.asarray(array, order=order, dtype=dtype)\n",
      "  File \"c:\\Python310\\lib\\site-packages\\pandas\\core\\generic.py\", line 2072, in __array__\n",
      "    return np.asarray(self._values, dtype=dtype)\n",
      "  File \"c:\\Python310\\lib\\site-packages\\pandas\\core\\frame.py\", line 918, in _values\n",
      "    return self.values\n",
      "  File \"c:\\Python310\\lib\\site-packages\\pandas\\core\\frame.py\", line 10877, in values\n",
      "    return self._mgr.as_array()\n",
      "  File \"c:\\Python310\\lib\\site-packages\\pandas\\core\\internals\\managers.py\", line 1589, in as_array\n",
      "    arr = self._interleave(dtype=dtype, na_value=na_value)\n",
      "  File \"c:\\Python310\\lib\\site-packages\\pandas\\core\\internals\\managers.py\", line 1628, in _interleave\n",
      "    result = np.empty(self.shape, dtype=dtype)\n",
      "numpy.core._exceptions._ArrayMemoryError: Unable to allocate 2.83 GiB for an array with shape (1077, 353191) and data type object\n",
      "\n",
      "--------------------------------------------------------------------------------\n",
      "1 fits failed with the following error:\n",
      "Traceback (most recent call last):\n",
      "  File \"c:\\Python310\\lib\\site-packages\\sklearn\\model_selection\\_validation.py\", line 680, in _fit_and_score\n",
      "    estimator.fit(X_train, y_train, **fit_params)\n",
      "  File \"c:\\Python310\\lib\\site-packages\\sklearn\\tree\\_classes.py\", line 937, in fit\n",
      "    super().fit(\n",
      "  File \"c:\\Python310\\lib\\site-packages\\sklearn\\tree\\_classes.py\", line 165, in fit\n",
      "    X, y = self._validate_data(\n",
      "  File \"c:\\Python310\\lib\\site-packages\\sklearn\\base.py\", line 578, in _validate_data\n",
      "    X = check_array(X, **check_X_params)\n",
      "  File \"c:\\Python310\\lib\\site-packages\\sklearn\\utils\\validation.py\", line 746, in check_array\n",
      "    array = np.asarray(array, order=order, dtype=dtype)\n",
      "  File \"c:\\Python310\\lib\\site-packages\\pandas\\core\\generic.py\", line 2072, in __array__\n",
      "    return np.asarray(self._values, dtype=dtype)\n",
      "  File \"c:\\Python310\\lib\\site-packages\\pandas\\core\\frame.py\", line 918, in _values\n",
      "    return self.values\n",
      "  File \"c:\\Python310\\lib\\site-packages\\pandas\\core\\frame.py\", line 10877, in values\n",
      "    return self._mgr.as_array()\n",
      "  File \"c:\\Python310\\lib\\site-packages\\pandas\\core\\internals\\managers.py\", line 1589, in as_array\n",
      "    arr = self._interleave(dtype=dtype, na_value=na_value)\n",
      "  File \"c:\\Python310\\lib\\site-packages\\pandas\\core\\internals\\managers.py\", line 1636, in _interleave\n",
      "    arr = blk.get_values(dtype)\n",
      "  File \"c:\\Python310\\lib\\site-packages\\pandas\\core\\internals\\blocks.py\", line 228, in get_values\n",
      "    return self.values.astype(_dtype_obj)\n",
      "numpy.core._exceptions._ArrayMemoryError: Unable to allocate 2.78 GiB for an array with shape (1056, 353192) and data type object\n",
      "\n",
      "  warnings.warn(some_fits_failed_message, FitFailedWarning)\n",
      "c:\\Python310\\lib\\site-packages\\sklearn\\model_selection\\_validation.py:372: FitFailedWarning: \n",
      "2 fits failed out of a total of 5.\n",
      "The score on these train-test partitions for these parameters will be set to nan.\n",
      "If these failures are not expected, you can try to debug them by setting error_score='raise'.\n",
      "\n",
      "Below are more details about the failures:\n",
      "--------------------------------------------------------------------------------\n",
      "1 fits failed with the following error:\n",
      "Traceback (most recent call last):\n",
      "  File \"c:\\Python310\\lib\\site-packages\\sklearn\\model_selection\\_validation.py\", line 680, in _fit_and_score\n",
      "    estimator.fit(X_train, y_train, **fit_params)\n",
      "  File \"c:\\Python310\\lib\\site-packages\\sklearn\\tree\\_classes.py\", line 937, in fit\n",
      "    super().fit(\n",
      "  File \"c:\\Python310\\lib\\site-packages\\sklearn\\tree\\_classes.py\", line 165, in fit\n",
      "    X, y = self._validate_data(\n",
      "  File \"c:\\Python310\\lib\\site-packages\\sklearn\\base.py\", line 578, in _validate_data\n",
      "    X = check_array(X, **check_X_params)\n",
      "  File \"c:\\Python310\\lib\\site-packages\\sklearn\\utils\\validation.py\", line 746, in check_array\n",
      "    array = np.asarray(array, order=order, dtype=dtype)\n",
      "  File \"c:\\Python310\\lib\\site-packages\\pandas\\core\\generic.py\", line 2072, in __array__\n",
      "    return np.asarray(self._values, dtype=dtype)\n",
      "  File \"c:\\Python310\\lib\\site-packages\\pandas\\core\\frame.py\", line 918, in _values\n",
      "    return self.values\n",
      "  File \"c:\\Python310\\lib\\site-packages\\pandas\\core\\frame.py\", line 10877, in values\n",
      "    return self._mgr.as_array()\n",
      "  File \"c:\\Python310\\lib\\site-packages\\pandas\\core\\internals\\managers.py\", line 1589, in as_array\n",
      "    arr = self._interleave(dtype=dtype, na_value=na_value)\n",
      "  File \"c:\\Python310\\lib\\site-packages\\pandas\\core\\internals\\managers.py\", line 1636, in _interleave\n",
      "    arr = blk.get_values(dtype)\n",
      "  File \"c:\\Python310\\lib\\site-packages\\pandas\\core\\internals\\blocks.py\", line 228, in get_values\n",
      "    return self.values.astype(_dtype_obj)\n",
      "numpy.core._exceptions._ArrayMemoryError: Unable to allocate 2.69 MiB for an array with shape (1, 353191) and data type object\n",
      "\n",
      "--------------------------------------------------------------------------------\n",
      "1 fits failed with the following error:\n",
      "Traceback (most recent call last):\n",
      "  File \"c:\\Python310\\lib\\site-packages\\sklearn\\model_selection\\_validation.py\", line 680, in _fit_and_score\n",
      "    estimator.fit(X_train, y_train, **fit_params)\n",
      "  File \"c:\\Python310\\lib\\site-packages\\sklearn\\tree\\_classes.py\", line 937, in fit\n",
      "    super().fit(\n",
      "  File \"c:\\Python310\\lib\\site-packages\\sklearn\\tree\\_classes.py\", line 165, in fit\n",
      "    X, y = self._validate_data(\n",
      "  File \"c:\\Python310\\lib\\site-packages\\sklearn\\base.py\", line 578, in _validate_data\n",
      "    X = check_array(X, **check_X_params)\n",
      "  File \"c:\\Python310\\lib\\site-packages\\sklearn\\utils\\validation.py\", line 746, in check_array\n",
      "    array = np.asarray(array, order=order, dtype=dtype)\n",
      "  File \"c:\\Python310\\lib\\site-packages\\pandas\\core\\generic.py\", line 2072, in __array__\n",
      "    return np.asarray(self._values, dtype=dtype)\n",
      "  File \"c:\\Python310\\lib\\site-packages\\pandas\\core\\frame.py\", line 918, in _values\n",
      "    return self.values\n",
      "  File \"c:\\Python310\\lib\\site-packages\\pandas\\core\\frame.py\", line 10877, in values\n",
      "    return self._mgr.as_array()\n",
      "  File \"c:\\Python310\\lib\\site-packages\\pandas\\core\\internals\\managers.py\", line 1589, in as_array\n",
      "    arr = self._interleave(dtype=dtype, na_value=na_value)\n",
      "  File \"c:\\Python310\\lib\\site-packages\\pandas\\core\\internals\\managers.py\", line 1628, in _interleave\n",
      "    result = np.empty(self.shape, dtype=dtype)\n",
      "numpy.core._exceptions._ArrayMemoryError: Unable to allocate 2.83 GiB for an array with shape (1077, 353191) and data type object\n",
      "\n",
      "  warnings.warn(some_fits_failed_message, FitFailedWarning)\n"
     ]
    }
   ],
   "source": [
    "# load model\n",
    "DTE_model = pickle.load(open('../01_solution_probability_model/02_decision_tree/Decisiontreemodel_3months.pkl', 'rb'))\n",
    "\n",
    "for (group, subgroup, matrice) in zip(group, subgroup, matrice):\n",
    "    print(matrice)\n",
    "    path= '../../04_bias_mitigation/07_data_dumps/'+matrice+'.pkl'\n",
    "    infile = open(path,'rb')\n",
    "    df = pickle.load(infile)\n",
    "    infile.close()\n",
    "\n",
    "    dataset= df[df.columns[df.columns.isin(feature_cols)]]\n",
    "    y = dataset['Erfolg']\n",
    "    X = dataset.drop(columns=['Erfolg'])\n",
    "    k = 5\n",
    "    cv = KFold(n_splits=k, random_state=None)\n",
    "    a,p,r,roc_auc,fpr = get_metrics(DTE_model,X,y,cv)\n",
    "    fair_metrics = fair_metrics.append({'model':'DTE','group':group,'subgroup':subgroup,'Accuracy':a,'Precision': p, 'Recall':r, 'AUC':roc_auc, 'FPR':fpr}, ignore_index=True)\n",
    "\n",
    "# fair_metrics.to_excel('dte_metrics.xlsx')\n",
    "# fair_metrics.to_pickle('dte_metrics.pkl')"
   ]
  },
  {
   "cell_type": "code",
   "execution_count": null,
   "metadata": {},
   "outputs": [
    {
     "data": {
      "text/html": [
       "<div>\n",
       "<style scoped>\n",
       "    .dataframe tbody tr th:only-of-type {\n",
       "        vertical-align: middle;\n",
       "    }\n",
       "\n",
       "    .dataframe tbody tr th {\n",
       "        vertical-align: top;\n",
       "    }\n",
       "\n",
       "    .dataframe thead th {\n",
       "        text-align: right;\n",
       "    }\n",
       "</style>\n",
       "<table border=\"1\" class=\"dataframe\">\n",
       "  <thead>\n",
       "    <tr style=\"text-align: right;\">\n",
       "      <th></th>\n",
       "      <th>model</th>\n",
       "      <th>group</th>\n",
       "      <th>subgroup</th>\n",
       "      <th>Accuracy</th>\n",
       "      <th>Precision</th>\n",
       "      <th>Recall</th>\n",
       "      <th>AUC</th>\n",
       "      <th>FPR</th>\n",
       "    </tr>\n",
       "  </thead>\n",
       "  <tbody>\n",
       "    <tr>\n",
       "      <th>0</th>\n",
       "      <td>DTE</td>\n",
       "      <td>abiEltern</td>\n",
       "      <td>abi</td>\n",
       "      <td>0.968314</td>\n",
       "      <td>0.993765</td>\n",
       "      <td>0.964872</td>\n",
       "      <td>0.972336</td>\n",
       "      <td>0.0202</td>\n",
       "    </tr>\n",
       "    <tr>\n",
       "      <th>1</th>\n",
       "      <td>DTE</td>\n",
       "      <td>abiEltern</td>\n",
       "      <td>keinAbi</td>\n",
       "      <td>0.972296</td>\n",
       "      <td>0.995658</td>\n",
       "      <td>0.967552</td>\n",
       "      <td>0.977255</td>\n",
       "      <td>0.013042</td>\n",
       "    </tr>\n",
       "    <tr>\n",
       "      <th>2</th>\n",
       "      <td>DTE</td>\n",
       "      <td>gender</td>\n",
       "      <td>boys</td>\n",
       "      <td>0.972505</td>\n",
       "      <td>0.994473</td>\n",
       "      <td>0.968784</td>\n",
       "      <td>0.976262</td>\n",
       "      <td>0.01626</td>\n",
       "    </tr>\n",
       "    <tr>\n",
       "      <th>3</th>\n",
       "      <td>DTE</td>\n",
       "      <td>gender</td>\n",
       "      <td>girls</td>\n",
       "      <td>0.970722</td>\n",
       "      <td>0.99457</td>\n",
       "      <td>0.967066</td>\n",
       "      <td>0.974883</td>\n",
       "      <td>0.0173</td>\n",
       "    </tr>\n",
       "    <tr>\n",
       "      <th>4</th>\n",
       "      <td>DTE</td>\n",
       "      <td>erstsprache</td>\n",
       "      <td>deutsch</td>\n",
       "      <td>0.969558</td>\n",
       "      <td>0.994364</td>\n",
       "      <td>0.965669</td>\n",
       "      <td>0.973936</td>\n",
       "      <td>0.017798</td>\n",
       "    </tr>\n",
       "    <tr>\n",
       "      <th>5</th>\n",
       "      <td>DTE</td>\n",
       "      <td>erstsprache</td>\n",
       "      <td>migration</td>\n",
       "      <td>0.974717</td>\n",
       "      <td>0.994791</td>\n",
       "      <td>0.971365</td>\n",
       "      <td>0.978063</td>\n",
       "      <td>0.01524</td>\n",
       "    </tr>\n",
       "    <tr>\n",
       "      <th>6</th>\n",
       "      <td>DTE</td>\n",
       "      <td>buecher</td>\n",
       "      <td>buch0</td>\n",
       "      <td>0.969827</td>\n",
       "      <td>0.99438</td>\n",
       "      <td>0.964104</td>\n",
       "      <td>0.974694</td>\n",
       "      <td>0.014716</td>\n",
       "    </tr>\n",
       "    <tr>\n",
       "      <th>7</th>\n",
       "      <td>DTE</td>\n",
       "      <td>buecher</td>\n",
       "      <td>buch1</td>\n",
       "      <td>0.97459</td>\n",
       "      <td>0.995196</td>\n",
       "      <td>0.970628</td>\n",
       "      <td>0.97843</td>\n",
       "      <td>0.013768</td>\n",
       "    </tr>\n",
       "  </tbody>\n",
       "</table>\n",
       "</div>"
      ],
      "text/plain": [
       "  model        group   subgroup  Accuracy Precision    Recall       AUC  \\\n",
       "0   DTE    abiEltern        abi  0.968314  0.993765  0.964872  0.972336   \n",
       "1   DTE    abiEltern    keinAbi  0.972296  0.995658  0.967552  0.977255   \n",
       "2   DTE       gender       boys  0.972505  0.994473  0.968784  0.976262   \n",
       "3   DTE       gender      girls  0.970722   0.99457  0.967066  0.974883   \n",
       "4   DTE  erstsprache    deutsch  0.969558  0.994364  0.965669  0.973936   \n",
       "5   DTE  erstsprache  migration  0.974717  0.994791  0.971365  0.978063   \n",
       "6   DTE      buecher      buch0  0.969827   0.99438  0.964104  0.974694   \n",
       "7   DTE      buecher      buch1   0.97459  0.995196  0.970628   0.97843   \n",
       "\n",
       "        FPR  \n",
       "0    0.0202  \n",
       "1  0.013042  \n",
       "2   0.01626  \n",
       "3    0.0173  \n",
       "4  0.017798  \n",
       "5   0.01524  \n",
       "6  0.014716  \n",
       "7  0.013768  "
      ]
     },
     "execution_count": 7,
     "metadata": {},
     "output_type": "execute_result"
    }
   ],
   "source": [
    "fair_metrics"
   ]
  },
  {
   "attachments": {},
   "cell_type": "markdown",
   "metadata": {},
   "source": [
    "Logistic Regression"
   ]
  },
  {
   "cell_type": "code",
   "execution_count": null,
   "metadata": {},
   "outputs": [],
   "source": [
    "# load model\n",
    "logreg_model = pickle.load(open('../03_prediction_solution_probability/03_logisticRegression/Logregmodel_3months.pkl', 'rb'))\n",
    "\n",
    "for (group, subgroup, matrice) in zip(group, subgroup, matrice):\n",
    "    path= matrice+'.pkl'\n",
    "    infile = open(path,'rb')\n",
    "    df = pickle.load(infile)\n",
    "    infile.close()\n",
    "\n",
    "    dataset = df[df.columns[df.columns.isin(feature_cols)]]\n",
    "    y = dataset['Erfolg']\n",
    "    X = dataset.drop(columns=['Erfolg'])\n",
    "\n",
    "    a,p,r,roc_auc,fpr = get_metrics(logreg_model,X,y)\n",
    "    fair_metrics = fair_metrics.append({'model':'LogReg','group':group,'subgroup':subgroup,'Accuracy':a,'Precision': p, 'Recall':r, 'AUC':roc_auc, 'FPR':fpr}, ignore_index=True)\n",
    "\n",
    "fair_metrics.to_excel('log_metrics.xlsx')\n",
    "fair_metrics.to_pickle('log_metrics.pkl')"
   ]
  },
  {
   "attachments": {},
   "cell_type": "markdown",
   "metadata": {},
   "source": [
    "SVM"
   ]
  },
  {
   "cell_type": "code",
   "execution_count": null,
   "metadata": {},
   "outputs": [],
   "source": [
    "# load model\n",
    "svm_model = pickle.load(open('../03_prediction_solution_probability/04_svm/SVMmodel_3months.pkl', 'rb'))\n",
    "\n",
    "for (group, subgroup, matrice) in zip(group, subgroup, matrice):\n",
    "    path= matrice+'.pkl'\n",
    "    infile = open(path,'rb')\n",
    "    df = pickle.load(infile)\n",
    "    infile.close()\n",
    "\n",
    "    dataset = df[df.columns[df.columns.isin(feature_cols)]]\n",
    "    y = dataset['Erfolg']\n",
    "    X = dataset.drop(columns=['Erfolg'])\n",
    "\n",
    "    a,p,r,roc_auc,fpr = get_metrics(svm_model,X,y)\n",
    "    fair_metrics = fair_metrics.append({'model':'SVM','group':group,'subgroup':subgroup,'Accuracy':a,'Precision': p, 'Recall':r, 'AUC':roc_auc, 'FPR':fpr}, ignore_index=True)\n",
    "\n",
    "fair_metrics.to_excel('svm_metrics.xlsx')\n",
    "fair_metrics.to_pickle('svm_metrics.pkl')"
   ]
  },
  {
   "attachments": {},
   "cell_type": "markdown",
   "metadata": {},
   "source": [
    "Neural Network"
   ]
  },
  {
   "cell_type": "code",
   "execution_count": null,
   "metadata": {},
   "outputs": [],
   "source": [
    "\"\"\"\n",
    "function to predict y in nn model\n",
    "return all metrics neccessary for fairness evaluation\n",
    "\"\"\"\n",
    "def get_dn_metrics(model, X,y):\n",
    "    X = np.asarray(X).astype('float32')\n",
    "    yhat_probs = model.predict(X, verbose=0)\n",
    "    yhat_classes =  (model.predict(X) > 0.5).astype(\"int32\")\n",
    "    # reduce to 1d array\n",
    "    yhat_probs = yhat_probs[:, 0]\n",
    "    yhat_classes = yhat_classes[:, 0]\n",
    "    a = accuracy_score(y, yhat_classes)\n",
    "    p = precision_score(y, yhat_classes)\n",
    "    r = recall_score(y, yhat_classes)\n",
    "    roc_auc = roc_auc_score(y, yhat_probs)\n",
    "    tn, fp, fn, tp = confusion_matrix(y, yhat_classes).ravel()\n",
    "    fpr = fp/(fp+tn)\n",
    "\n",
    "    return a,p,r,roc_auc,fpr\n",
    "\n",
    "\n",
    "# load model\n",
    "nn_model = load_model('../03_prediction_solution_probability/05_nn/nn_3months/')\n",
    "\n",
    "for (group, subgroup, matrice) in zip(group, subgroup, matrice):\n",
    "    path= matrice+'.pkl'\n",
    "    infile = open(path,'rb')\n",
    "    df = pickle.load(infile)\n",
    "    infile.close()\n",
    "\n",
    "    dataset = df[df.columns[df.columns.isin(feature_cols)]]\n",
    "    y = dataset['Erfolg']\n",
    "    X = dataset.drop(columns=['Erfolg'])\n",
    "\n",
    "    a,p,r,roc_auc,fpr = get_dn_metrics(nn_model,X,y)\n",
    "    fair_metrics = fair_metrics.append({'model':'NN','group':group,'subgroup':subgroup,'Accuracy':a,'Precision': p, 'Recall':r, 'AUC':roc_auc, 'FPR':fpr}, ignore_index=True)\n",
    "\n",
    "fair_metrics.to_excel('nn_metrics.xlsx')\n",
    "fair_metrics.to_pickle('nn_metrics.pkl')"
   ]
  }
 ],
 "metadata": {
  "kernelspec": {
   "display_name": "Python 3.10.2 64-bit",
   "language": "python",
   "name": "python3"
  },
  "language_info": {
   "codemirror_mode": {
    "name": "ipython",
    "version": 3
   },
   "file_extension": ".py",
   "mimetype": "text/x-python",
   "name": "python",
   "nbconvert_exporter": "python",
   "pygments_lexer": "ipython3",
   "version": "3.10.2"
  },
  "orig_nbformat": 4,
  "vscode": {
   "interpreter": {
    "hash": "369f2c481f4da34e4445cda3fffd2e751bd1c4d706f27375911949ba6bb62e1c"
   }
  }
 },
 "nbformat": 4,
 "nbformat_minor": 2
}
